Traceback (most recent call last):
  File "/opt/hostedtoolcache/Python/3.10.18/x64/lib/python3.10/site-packages/jupyter_cache/executors/utils.py", line 58, in single_nb_execution
    executenb(
  File "/opt/hostedtoolcache/Python/3.10.18/x64/lib/python3.10/site-packages/nbclient/client.py", line 1319, in execute
    return NotebookClient(nb=nb, resources=resources, km=km, **kwargs).execute()
  File "/opt/hostedtoolcache/Python/3.10.18/x64/lib/python3.10/site-packages/jupyter_core/utils/__init__.py", line 165, in wrapped
    return loop.run_until_complete(inner)
  File "/opt/hostedtoolcache/Python/3.10.18/x64/lib/python3.10/asyncio/base_events.py", line 649, in run_until_complete
    return future.result()
  File "/opt/hostedtoolcache/Python/3.10.18/x64/lib/python3.10/site-packages/nbclient/client.py", line 709, in async_execute
    await self.async_execute_cell(
  File "/opt/hostedtoolcache/Python/3.10.18/x64/lib/python3.10/site-packages/nbclient/client.py", line 1062, in async_execute_cell
    await self._check_raise_for_error(cell, cell_index, exec_reply)
  File "/opt/hostedtoolcache/Python/3.10.18/x64/lib/python3.10/site-packages/nbclient/client.py", line 918, in _check_raise_for_error
    raise CellExecutionError.from_cell_and_msg(cell, exec_reply_content)
nbclient.exceptions.CellExecutionError: An error occurred while executing the following cell:
------------------
import openeo

connection = openeo.connect("openeo.dataspace.copernicus.eu").authenticate_oidc()

aoi = {
    "type": "Polygon",
    "coordinates": [
        [
            [
              112.84,
              -7.16
            ],
            [
              112.84,
              -7.17
            ],
            [
              112.85,
              -7.166
            ],
            [
              112.85,
              -7.16
            ],
            [
              112.84,
              -7.16
            ]
        ]
    ],
    "type": "Polygon"   
}

s5p_no2 = connection.load_collection(
    "SENTINEL_5P_L2",
    temporal_extent=["2023-10-15", "2025-10-19"],
    spatial_extent={
        "west": 112.84,
        "south": -7.17,
        "east": 112.86,
        "north": -7.15
    },
    bands=["NO2"]
)

# 4. Hitung rata-rata harian
s5p_no2_daily = s5p_no2.aggregate_temporal_period(
    period="day",
    reducer="mean"
)

# 5. Hitung rata-rata spasial berdasarkan AOI
s5p_no2_aoi = s5p_no2_daily.aggregate_spatial(
    geometries=aoi,
    reducer="mean"
)

job = s5p_no2.execute_batch(title="NO2 in Kwanyar", outputfile="NO2_in_Kwanyar.nc")
------------------


[0;31m---------------------------------------------------------------------------[0m
[0;31mModuleNotFoundError[0m                       Traceback (most recent call last)
Cell [0;32mIn[1], line 1[0m
[0;32m----> 1[0m [38;5;28;01mimport[39;00m[38;5;250m [39m[38;5;21;01mopeneo[39;00m
[1;32m      3[0m connection [38;5;241m=[39m openeo[38;5;241m.[39mconnect([38;5;124m"[39m[38;5;124mopeneo.dataspace.copernicus.eu[39m[38;5;124m"[39m)[38;5;241m.[39mauthenticate_oidc()
[1;32m      5[0m aoi [38;5;241m=[39m {
[1;32m      6[0m     [38;5;124m"[39m[38;5;124mtype[39m[38;5;124m"[39m: [38;5;124m"[39m[38;5;124mPolygon[39m[38;5;124m"[39m,
[1;32m      7[0m     [38;5;124m"[39m[38;5;124mcoordinates[39m[38;5;124m"[39m: [
[0;32m   (...)[0m
[1;32m     31[0m     [38;5;124m"[39m[38;5;124mtype[39m[38;5;124m"[39m: [38;5;124m"[39m[38;5;124mPolygon[39m[38;5;124m"[39m   
[1;32m     32[0m }

[0;31mModuleNotFoundError[0m: No module named 'openeo'

